<?xml version="1.0"?>

<robot name="jeepModel">

  <!-- Center Base with Jeep Model -->
  <link name="base_link">
    <visual>
      <geometry>
        <mesh filename="package://ros_robotics/meshes/JEEP.xml" scale="1 1 1"/>
      </geometry>
      <origin rpy="1.57079 0 0" xyz="0 -0.305 0"/>
    </visual>
  </link>

  <!-- Sensor Platform Base -->
  <link name="sensor_platform">
    <visual>
      <geometry>
        <box size="0.12 0.3 0.0078"/>
      </geometry>
      <origin rpy="0 0 0" xyz="0 0.0 0"/>
    </visual>
  </link>

  <!-- Front Left Wheel -->
  <link name="wheel_front_left">
    <visual>
      <geometry>
        <mesh filename="package://ros_robotics/meshes/Wheel.stl" scale="0.001 0.001 0.001"/>
      </geometry>
      <origin rpy="1.57075 0 0" xyz="0 0 0"/>
    </visual>
  </link>

  <!-- Front Right Wheel -->
  <link name="wheel_front_right">
    <visual>
      <geometry>
        <mesh filename="package://ros_robotics/meshes/Wheel.stl" scale="0.001 0.001 0.001"/>
      </geometry>
      <origin rpy="1.57075 0 0" xyz="0 0 0"/>
    </visual>
  </link>

  <!-- Back Left Wheel -->
    <link name="wheel_back_left">
      <visual>
        <geometry>
          <mesh filename="package://ros_robotics/meshes/Wheel.stl" scale="0.001 0.001 0.001"/>
        </geometry>
        <origin rpy="1.57075 0 0" xyz="0 0 0"/>
      </visual>
    </link>

  <!-- Back Right Wheel -->
    <link name="wheel_back_right">
     <visual>
      <geometry>
        <mesh filename="package://ros_robotics/meshes/Wheel.stl" scale="0.001 0.001 0.001"/>
      </geometry>
      <origin rpy="1.57075 0 0" xyz="0 0 0"/>
     </visual>
    </link>


                        <!-- Joints are located below -->

<!-- Jeep Base to Sensor Platform Joint -->
  <joint name="sensor_platform_to_base_link" type="fixed">
    <parent link="base_link"/>
    <child link="sensor_platform"/>
    <origin rpy="0 0 0" xyz="-0.09 0 0.57"/>
  </joint>

<!-- Jeep Base to Front Left Wheel -->
  <joint name="base_to_wheel_front_left" type="continuous">
    <parent link="base_link"/>
    <child link="wheel_front_left"/>
    <origin rpy="0 0 0" xyz="0.71 0.305 0"/>
  </joint>

<!-- Jeep Base to Front Right Wheel -->
  <joint name="base_to_wheel_front_right" type="continuous">
    <parent link="base_link"/>
    <child link="wheel_front_right"/>
    <origin rpy="0 0 0" xyz="0.71 -0.305 0"/>
  </joint>

<!-- Jeep Base to Back Left Wheel -->
  <joint name="base_to_wheel_back_left" type="continuous">
	  <parent link="base_link"/>
    <child link="wheel_back_left"/>
    <origin rpy="0 0 0" xyz="0 0.305 0"/>
  </joint>


  <joint name="base_to_wheel_back_right" type="continuous">
  	 <parent link="base_link"/>
  	 <child link="wheel_back_right"/>
  	 <origin rpy="0 0 0" xyz="0 -0.305 0"/>
  </joint>

</robot>
